<mujoco model="simple_gripper">
  <default>
    <joint armature="0.1" damping="0.2" limited="true"/>
    </default>
  <worldbody>
    <body name="worldBody" pos="0 0 0">
      <geom name="base_geom" type="capsule" size="0.01" fromto="0 0 0 0 0 0.02"/>
      <body name="finger_left" pos="0 0.003 0">
        <joint name="joint_left" type="hinge" axis="-1 0 0" range="0 90"/>
        <geom name="finger_left_geom" type="box" pos="0 0.04 0" size="0.005 0.03 0.002"/>
      </body>
      <body name="finger_right" pos="0 -0.003 0">
        <joint name="joint_right" type="hinge" axis="1 0 0" range="0 90"/>
        <geom name="finger_right_geom" type="box" pos="0 -0.04 0" size="0.005 0.03 0.002"/>
      </body>
    </body>
  </worldbody>
  <actuator>
    <position name="act_left" joint="joint_left" ctrlrange="0 1.57"/>
    <position name="act_right" joint="joint_right" ctrlrange="0 1.57"/>
  </actuator>
</mujoco>
